Workbook

Sheet Cars
A1: Name | B1: Manufacturer | C1: Year | D1: Model | E1: Type | F1: Rarity | G1: =$F1 -> Rarity | H1: Country | I1: Value | J1: Super Wheelspins (pre Series 4) | K1: Wheelspins (pre Series 4) | L1: Skill-Points (pre Series 4) | M1: Expected Gain per Skill-Point when owned (pre Series 4) | N1: Expected Gain per Skill-Point when buying (pre Series 4)
A2: Abarth 595 '68 | B2: Abarth | C2: 1968 | D2: Abarth 595 esseesse | E2: Cult Classics | F2: =IF(ISBLANK($G2),,VLOOKUP($G2, Rarities!$A$1:$B869, 2, FALSE())) -> 1 | G2: Common | H2: =VLOOKUP(B2,Manufacturers!A$1:B869,2) -> IT | I2: 35000
A3: Abarth 131 | B3: Abarth | C3: 1980 | D3: Fiat 131 | E3: Classic Rally | F3: =IF(ISBLANK($G3),,VLOOKUP($G3, Rarities!$A$1:$B869, 2, FALSE())) -> 1 | G3: Common | H3: =VLOOKUP(B3,Manufacturers!A$1:B869,2) -> IT | I3: 250000
A4: Abarth 695 '16 | B4: Abarth | C4: 2016 | D4: 695 Biposto | E4: Hot Hatch | F4: =IF(ISBLANK($G4),,VLOOKUP($G4, Rarities!$A$1:$B869, 2, FALSE())) -> 1 | G4: Common | H4: =VLOOKUP(B4,Manufacturers!A$1:B869,2) -> IT | I4: 250000
A5: Abarth 124 '17 | B5: Abarth | C5: 2017 | D5: 124 Spider | E5: Modern Sports Cars | F5: =IF(ISBLANK($G5),,VLOOKUP($G5, Rarities!$A$1:$B869, 2, FALSE())) -> 1 | G5: Common | H5: =VLOOKUP(B5,Manufacturers!A$1:B869,2) -> IT | I5: 250000
A6: Acura Integra | B6: Acura | C6: 2001 | D6: Integra Type R | E6: Retro Hot Hatch | F6: =IF(ISBLANK($G6),,VLOOKUP($G6, Rarities!$A$1:$B869, 2, FALSE())) -> 1 | G6: Common | H6: =VLOOKUP(B6,Manufacturers!A$1:B869,2) -> US | I6: 25000 | K6: 1 | L6: 9 | M6: =IF(AND(ISNUMBER(L6),L6>0),(3*J6+K6)*#REF!/L6,"-") -> #REF! | N6: =IF(AND(#REF!,ISNUMBER(L6),L6>0),((3*J6+K6)*#REF!-I6)/L6,"-") -> #REF!
A7: Acura RSX | B7: Acura | C7: 2002 | D7: RSX Type S | E7: Retro Hot Hatch | F7: =IF(ISBLANK($G7),,VLOOKUP($G7, Rarities!$A$1:$B869, 2, FALSE())) -> 1 | G7: Common | H7: =VLOOKUP(B7,Manufacturers!A$1:B869,2) -> US | I7: 25000 | K7: 1 | L7: 9 | M7: =IF(AND(ISNUMBER(L7),L7>0),(3*J7+K7)*#REF!/L7,"-") -> #REF! | N7: =IF(AND(#REF!,ISNUMBER(L7),L7>0),((3*J7+K7)*#REF!-I7)/L7,"-") -> #REF!
A8: Acura NSX '17 | B8: Acura | C8: 2017 | D8: NSX | E8: Modern Supercars | F8: =IF(ISBLANK($G8),,VLOOKUP($G8, Rarities!$A$1:$B869, 2, FALSE())) -> 2 | G8: Rare | H8: =VLOOKUP(B8,Manufacturers!A$1:B869,2) -> US | I8: 170000 | K8: 1 | L8: 9 | M8: =IF(AND(ISNUMBER(L8),L8>0),(3*J8+K8)*#REF!/L8,"-") -> #REF! | N8: =IF(AND(#REF!,ISNUMBER(L8),L8>0),((3*J8+K8)*#REF!-I8)/L8,"-") -> #REF!
A9: Alfa Romeo TZ2 | B9: Alfa Romeo | C9: 1965 | D9: Giulia TZ2 | E9: Classic Racers | F9: =IF(ISBLANK($G9),,VLOOKUP($G9, Rarities!$A$1:$B869, 2, FALSE())) -> 4 | G9: Legendary | H9: =VLOOKUP(B9,Manufacturers!A$1:B869,2) -> IT | I9: 4000000
A10: Alfa Romeo GTA | B10: Alfa Romeo | C10: 1965 | D10: Giulia Sprint GTA Stradale | E10: Rare Classics | F10: =IF(ISBLANK($G10),,VLOOKUP($G10, Rarities!$A$1:$B869, 2, FALSE())) -> 2 | G10: Rare | H10: =VLOOKUP(B10,Manufacturers!A$1:B869,2) -> IT | I10: 300000
A11: Alfa Romeo 33S | B11: Alfa Romeo | C11: 1968 | D11: 33 Stradale | E11: Classic Racers | F11: =IF(ISBLANK($G11),,VLOOKUP($G11, Rarities!$A$1:$B869, 2, FALSE())) -> 4 | G11: Legendary | H11: =VLOOKUP(B11,Manufacturers!A$1:B869,2) -> IT | I11: 15000000
A12: Alfa Romeo 155 | B12: Alfa Romeo | C12: 1992 | D12: 155 Q4 | E12: Retro Saloons | F12: =IF(ISBLANK($G12),,VLOOKUP($G12, Rarities!$A$1:$B869, 2, FALSE())) -> 1 | G12: Common | H12: =VLOOKUP(B12,Manufacturers!A$1:B869,2) -> IT | I12: 250000
A13: Alfa Romeo 8C | B13: Alfa Romeo | C13: 2007 | D13: 8C Competizione | E13: GT Cars | F13: =IF(ISBLANK($G13),,VLOOKUP($G13, Rarities!$A$1:$B869, 2, FALSE())) -> 3 | G13: Epic | H13: =VLOOKUP(B13,Manufacturers!A$1:B869,2) -> IT | I13: 300000
A14: Alfa Romeo 4C | B14: Alfa Romeo | C14: 2014 | D14: 4C | E14: Modern Sports Cars | F14: =IF(ISBLANK($G14),,VLOOKUP($G14, Rarities!$A$1:$B869, 2, FALSE())) -> 2 | G14: Rare | H14: =VLOOKUP(B14,Manufacturers!A$1:B869,2) -> IT | I14: 250000
A15: Alfa Giulia '17 | B15: Alfa Romeo | C15: 2017 | D15: Giulia Quadrifoglio | E15: Super Saloons | F15: =IF(ISBLANK($G15),,VLOOKUP($G15, Rarities!$A$1:$B869, 2, FALSE())) -> 2 | G15: Rare | H15: =VLOOKUP(B15,Manufacturers!A$1:B869,2) -> IT | I15: 120000
A16: Alpine A110 '73 | B16: Alpine | C16: 1973 | D16: A110 1600S | E16: Classic Rally | F16: =IF(ISBLANK($G16),,VLOOKUP($G16, Rarities!$A$1:$B869, 2, FALSE())) -> 2 | G16: Rare | H16: =VLOOKUP(B16,Manufacturers!A$1:B869,2) -> FR | I16: 98000 | K16: 1 | L16: 9 | M16: =IF(AND(ISNUMBER(L16),L16>0),(3*J16+K16)*#REF!/L16,"-") -> #REF! | N16: =IF(AND(#REF!,ISNUMBER(L16),L16>0),((3*J16+K16)*#REF!-I16)/L16,"-") -> #REF!
A17: Alpine A110 '17 | B17: Alpine | C17: 2017 | D17: A110 | E17: Modern Sports Cars | F17: =IF(ISBLANK($G17),,VLOOKUP($G17, Rarities!$A$1:$B869, 2, FALSE())) -> 3 | G17: Epic | H17: =VLOOKUP(B17,Manufacturers!A$1:B869,2) -> FR | I17: 67500 | K17: 1 | L17: 14 | M17: =IF(AND(ISNUMBER(L17),L17>0),(3*J17+K17)*#REF!/L17,"-") -> #REF! | N17: =IF(AND(#REF!,ISNUMBER(L17),L17>0),((3*J17+K17)*#REF!-I17)/L17,"-") -> #REF!
A18: Alumni Craft C. 10 | B18: Alumnicraft | C18: 2015 | D18: Class 10 Race Car | E18: Unlimited Buggies | F18: =IF(ISBLANK($G18),,VLOOKUP($G18, Rarities!$A$1:$B869, 2, FALSE())) -> 3 | G18: Epic | H18: =VLOOKUP(B18,Manufacturers!A$1:B869,2) -> US | I18: 300000 | K18: 2 | L18: 16 | M18: =IF(AND(ISNUMBER(L18),L18>0),(3*J18+K18)*#REF!/L18,"-") -> #REF! | N18: =IF(AND(#REF!,ISNUMBER(L18),L18>0),((3*J18+K18)*#REF!-I18)/L18,"-") -> #REF!
A19: #122 AC Class 1 | B19: Alumnicraft | C19: 2021 | D19: #122 Class 1 Buggy | E19: Unlimited Buggies | F19: =IF(ISBLANK($G19),,VLOOKUP($G19, Rarities!$A$1:$B869, 2, FALSE())) -> 3 | G19: Epic | H19: =VLOOKUP(B19,Manufacturers!A$1:B869,2) -> US | I19: 300000
A20: #6165 Truck | B20: Alumnicraft | C20: 2022 | D20: #6165 Trick Truck | E20: Unlimited Offroad | F20: =IF(ISBLANK($G20),,VLOOKUP($G20, Rarities!$A$1:$B869, 2, FALSE())) -> 3 | G20: Epic | H20: =VLOOKUP(B20,Manufacturers!A$1:B869,2) -> US | I20: 500000
A21: AMC Rebel | B21: AMC | C21: 1970 | D21: Rebel "The Machine" | E21: Classic Muscle | F21: =IF(ISBLANK($G21),,VLOOKUP($G21, Rarities!$A$1:$B869, 2, FALSE())) -> 2 | G21: Rare | H21: =VLOOKUP(B21,Manufacturers!A$1:B869,2) -> US | I21: 250000
A22: AMC Javelin | B22: AMC | C22: 1971 | D22: Javelin AMX | E22: Classic Muscle | F22: =IF(ISBLANK($G22),,VLOOKUP($G22, Rarities!$A$1:$B869, 2, FALSE())) -> 2 | G22: Rare | H22: =VLOOKUP(B22,Manufacturers!A$1:B869,2) -> US | I22: 250000
A23: AMC Gremlin | B23: AMC | C23: 1973 | D23: Gremlin X | E23: Cult Classics | F23: =IF(ISBLANK($G23),,VLOOKUP($G23, Rarities!$A$1:$B869, 2, FALSE())) -> 1 | G23: Common | H23: =VLOOKUP(B23,Manufacturers!A$1:B869,2) -> US | I23: 35000 | K23: 1 | L23: 9 | M23: =IF(AND(ISNUMBER(L23),L23>0),(3*J23+K23)*#REF!/L23,"-") -> #REF! | N23: =IF(AND(#REF!,ISNUMBER(L23),L23>0),((3*J23+K23)*#REF!-I23)/L23,"-") -> #REF!
A24: M12S Warthog CST | B24: AMG Transport Dynamics | C24: 2554 | D24: M12S Warthog CST | E24: Unlimited Offroad | F24: =IF(ISBLANK($G24),,VLOOKUP($G24, Rarities!$A$1:$B869, 2, FALSE())) -> 4 | G24: Legendary | H24: =VLOOKUP(B24,Manufacturers!A$1:B869,2) -> US | I24: 850000 | K24: 2 | L24: 9 | M24: =IF(AND(ISNUMBER(L24),L24>0),(3*J24+K24)*#REF!/L24,"-") -> #REF! | N24: =IF(AND(#REF!,ISNUMBER(L24),L24>0),((3*J24+K24)*#REF!-I24)/L24,"-") -> #REF!
A25: Apollo IE '18 | B25: Apollo | C25: 2018 | D25: Intensa Emozione | E25: Extreme Track Toys | F25: =IF(ISBLANK($G25),,VLOOKUP($G25, Rarities!$A$1:$B869, 2, FALSE())) -> 4 | G25: Legendary | H25: =VLOOKUP(B25,Manufacturers!A$1:B869,2) -> DE | I25: 1500000 | K25: 2 | L25: 13 | M25: =IF(AND(ISNUMBER(L25),L25>0),(3*J25+K25)*#REF!/L25,"-") -> #REF! | N25: =IF(AND(#REF!,ISNUMBER(L25),L25>0),((3*J25+K25)*#REF!-I25)/L25,"-") -> #REF!
A26: Apollo IE WP | B26: Apollo | C26: 2018 | D26: Intensa Emozione "Welcome Pack" | E26: Extreme Track Toys | F26: =IF(ISBLANK($G26),,VLOOKUP($G26, Rarities!$A$1:$B869, 2, FALSE())) -> 1 | G26: Common | H26: =VLOOKUP(B26,Manufacturers!A$1:B869,2) -> DE | I26: 1500000 | K26: 2 | L26: 13 | M26: =IF(AND(ISNUMBER(L26),L26>0),(3*J26+K26)*#REF!/L26,"-") -> #REF! | N26: =IF(AND(#REF!,ISNUMBER(L26),L26>0),((3*J26+K26)*#REF!-I26)/L26,"-") -> #REF!
A27: Ariel Atom | B27: Ariel | C27: 2013 | D27: Atom 500 V8 | E27: Extreme Track Toys | F27: =IF(ISBLANK($G27),,VLOOKUP($G27, Rarities!$A$1:$B869, 2, FALSE())) -> 3 | G27: Epic | H27: =VLOOKUP(B27,Manufacturers!A$1:B869,2) -> GB | I27: 200000 | K27: 2 | L27: 11 | M27: =IF(AND(ISNUMBER(L27),L27>0),(3*J27+K27)*#REF!/L27,"-") -> #REF! | N27: =IF(AND(#REF!,ISNUMBER(L27),L27>0),((3*J27+K27)*#REF!-I27)/L27,"-") -> #REF!
A28: Ariel Nomad | B28: Ariel | C28: 2016 | D28: Nomad | E28: Unlimited Buggies | F28: =IF(ISBLANK($G28),,VLOOKUP($G28, Rarities!$A$1:$B869, 2, FALSE())) -> 2 | G28: Rare | H28: =VLOOKUP(B28,Manufacturers!A$1:B869,2) -> GB | I28: 93000 | K28: 1 | L28: 14 | M28: =IF(AND(ISNUMBER(L28),L28>0),(3*J28+K28)*#REF!/L28,"-") -> #REF! | N28: =IF(AND(#REF!,ISNUMBER(L28),L28>0),((3*J28+K28)*#REF!-I28)/L28,"-") -> #REF!
A29: Ascari KZ1R | B29: Ascari | C29: 2012 | D29: KZ1R | E29: Modern Supercars | F29: =IF(ISBLANK($G29),,VLOOKUP($G29, Rarities!$A$1:$B869, 2, FALSE())) -> 3 | G29: Epic | H29: =VLOOKUP(B29,Manufacturers!A$1:B869,2) -> GB | I29: 250000
A30: AM DBR1 | B30: Aston Martin | C30: 1958 | D30: DBR1 | E30: Classic Racers | F30: =IF(ISBLANK($G30),,VLOOKUP($G30, Rarities!$A$1:$B869, 2, FALSE())) -> 4 | G30: Legendary | H30: =VLOOKUP(B30,Manufacturers!A$1:B869,2) -> GB | I30: 22500000
A31: AM DB5 | B31: Aston Martin | C31: 1964 | D31: DB5 | E31: Rare Classics | F31: =IF(ISBLANK($G31),,VLOOKUP($G31, Rarities!$A$1:$B869, 2, FALSE())) -> 3 | G31: Epic | H31: =VLOOKUP(B31,Manufacturers!A$1:B869,2) -> GB | I31: 800000 | K31: 2 | L31: 11 | M31: =IF(AND(ISNUMBER(L31),L31>0),(3*J31+K31)*#REF!/L31,"-") -> #REF! | N31: =IF(AND(#REF!,ISNUMBER(L31),L31>0),((3*J31+K31)*#REF!-I31)/L31,"-") -> #REF!
A32: AM DBS | B32: Aston Martin | C32: 2008 | D32: DBS | E32: GT Cars | F32: =IF(ISBLANK($G32),,VLOOKUP($G32, Rarities!$A$1:$B869, 2, FALSE())) -> 3 | G32: Epic | H32: =VLOOKUP(B32,Manufacturers!A$1:B869,2) -> GB | I32: 325000
A33: AM One-77 | B33: Aston Martin | C33: 2010 | D33: One-77 | E33: Super GT | F33: =IF(ISBLANK($G33),,VLOOKUP($G33, Rarities!$A$1:$B869, 2, FALSE())) -> 4 | G33: Legendary | H33: =VLOOKUP(B33,Manufacturers!A$1:B869,2) -> GB | I33: 1400000
A34: Vantage S '13 | B34: Aston Martin | C34: 2013 | D34: V12 Vantage S | E34: Super GT | F34: =IF(ISBLANK($G34),,VLOOKUP($G34, Rarities!$A$1:$B869, 2, FALSE())) -> 3 | G34: Epic | H34: =VLOOKUP(B34,Manufacturers!A$1:B869,2) -> GB | I34: 240000 | K34: 1 | L34: 14 | M34: =IF(AND(ISNUMBER(L34),L34>0),(3*J34+K34)*#REF!/L34,"-") -> #REF! | N34: =IF(AND(#REF!,ISNUMBER(L34),L34>0),((3*J34+K34)*#REF!-I34)/L34,"-") -> #REF!
A35: AM Vantage '16 | B35: Aston Martin | C35: 2016 | D35: Vantage GT12 | E35: Track Toys | F35: =IF(ISBLANK($G35),,VLOOKUP($G35, Rarities!$A$1:$B869, 2, FALSE())) -> 3 | G35: Epic | H35: =VLOOKUP(B35,Manufacturers!A$1:B869,2) -> GB | I35: 400000 | K35: 1 | L35: 9 | M35: =IF(AND(ISNUMBER(L35),L35>0),(3*J35+K35)*#REF!/L35,"-") -> #REF! | N35: =IF(AND(#REF!,ISNUMBER(L35),L35>0),((3*J35+K35)*#REF!-I35)/L35,"-") -> #REF!
A36: AM Vulcan AMR | B36: Aston Martin | C36: 2017 | D36: Vulcan AMR Pro | E36: Extreme Track Toys | F36: =IF(ISBLANK($G36),,VLOOKUP($G36, Rarities!$A$1:$B869, 2, FALSE())) -> 4 | G36: Legendary | H36: =VLOOKUP(B36,Manufacturers!A$1:B869,2) -> GB | I36: 2000000 | K36: 2 | L36: 11 | M36: =IF(AND(ISNUMBER(L36),L36>0),(3*J36+K36)*#REF!/L36,"-") -> #REF! | N36: =IF(AND(#REF!,ISNUMBER(L36),L36>0),((3*J36+K36)*#REF!-I36)/L36,"-") -> #REF!
A37: AM DB11 | B37: Aston Martin | C37: 2017 | D37: DB11 | E37: Super GT | F37: =IF(ISBLANK($G37),,VLOOKUP($G37, Rarities!$A$1:$B869, 2, FALSE())) -> 3 | G37: Epic | H37: =VLOOKUP(B37,Manufacturers!A$1:B869,2) -> GB | I37: 300000 | K37: 1 | L37: 14 | M37: =IF(AND(ISNUMBER(L37),L37>0),(3*J37+K37)*#REF!/L37,"-") -> #REF! | N37: =IF(AND(#REF!,ISNUMBER(L37),L37>0),((3*J37+K37)*#REF!-I37)/L37,"-") -> #REF!
A38: Valhalla Concept | B38: Aston Martin | C38: 2019 | D38: Valhalla Concept Car | E38: Hypercars | F38: =IF(ISBLANK($G38),,VLOOKUP($G38, Rarities!$A$1:$B869, 2, FALSE())) -> 4 | G38: Legendary | H38: =VLOOKUP(B38,Manufacturers!A$1:B869,2) -> GB | I38: 1150000 | J38: 2 | K38: 1 | L38: 21 | M38: =IF(AND(ISNUMBER(L38),L38>0),(3*J38+K38)*#REF!/L38,"-") -> #REF! | N38: =IF(AND(#REF!,ISNUMBER(L38),L38>0),((3*J38+K38)*#REF!-I38)/L38,"-") -> #REF!
A39: AM DBS SL '19 | B39: Aston Martin | C39: 2019 | D39: DBS Superleggera | E39: Super GT | F39: =IF(ISBLANK($G39),,VLOOKUP($G39, Rarities!$A$1:$B869, 2, FALSE())) -> 3 | G39: Epic | H39: =VLOOKUP(B39,Manufacturers!A$1:B869,2) -> GB | I39: 350000 | K39: 1 | L39: 14 | M39: =IF(AND(ISNUMBER(L39),L39>0),(3*J39+K39)*#REF!/L39,"-") -> #REF! | N39: =IF(AND(#REF!,ISNUMBER(L39),L39>0),((3*J39+K39)*#REF!-I39)/L39,"-") -> #REF!
A40: AM Vantage '19 | B40: Aston Martin | C40: 2019 | D40: Vantage | E40: GT Cars | F40: =IF(ISBLANK($G40),,VLOOKUP($G40, Rarities!$A$1:$B869, 2, FALSE())) -> 3 | G40: Epic | H40: =VLOOKUP(B40,Manufacturers!A$1:B869,2) -> GB | I40: 430000 | K40: 1 | L40: 14 | M40: =IF(AND(ISNUMBER(L40),L40>0),(3*J40+K40)*#REF!/L40,"-") -> #REF! | N40: =IF(AND(#REF!,ISNUMBER(L40),L40>0),((3*J40+K40)*#REF!-I40)/L40,"-") -> #REF!
...

Sheet Updates
A1: Name | B1: Date
A2: Base Game | B2: 44505
A3: Series 2 | B3: 44533
A4: Series 4 | B4: 44593
A5: Series 5 | B5: 44621
A6: Series 6 | B6: 44650
A7: Series 7 | B7: 44677
A8: Series 9 | B8: 44733
A9: Series 10 | B9: 44761
A10: Series 11 | B10: 44789
A11: Series 12 | B11: 44817
A12: Series 13 | B12: 44845
A13: Series 14 | B13: 44873
... A30: Series 33 | B30: 45405

Sheet DLCs
A1: Name | B1: Release Date | C1: Have
A2: Make-Up | B2: 44593 | C2: =FALSE() -> FALSE
A3: Controller | B3: 44505 | C3: =FALSE() -> FALSE
A4: Formula Drift Pack | B4: 44505 | C4: =TRUE() -> TRUE
A5: VIP | B5: 44505 | C5: =TRUE() -> TRUE
A6: Welcome Pack | B6: 44505 | C6: =TRUE() -> TRUE
A7: Hot Wheels | B7: 44761 | C7: =TRUE() -> TRUE
A8: Oreo | B8: 44957 | C8: =TRUE() -> TRUE
A9: Rally | B9: 45014 | C9: =TRUE() -> TRUE
A10: Horizon Racing Pack | B10: 45097 | C10: =TRUE() -> TRUE
A11: Italian Exotics Pack | B11: 45153 | C11: =TRUE() -> TRUE
A12: Forza Motorsport 8 | B12: 45204 | C12: =TRUE() -> TRUE
A13: Super Speed Pack | B13: 45209 | C13: =TRUE() -> TRUE
A14: American Automotive Pack | B14: 45237 | C14: =TRUE() -> TRUE
A15: Fast X Pack | B15: 45265 | C15: =TRUE() -> TRUE
... A18: European Automotive Pack | B18: 45349 | C18: =TRUE() -> TRUE
A19: Acceleration Pack | B19: 45377 | C19: =FALSE() -> FALSE
A20: Apex Allstars Pack | B20: 45405 | C20: =FALSE() -> FALSE
C21: =FALSE() -> FALSE
C22: =FALSE() -> FALSE
C23: =FALSE() -> FALSE
C24: =FALSE() -> FALSE
C25: =FALSE() -> FALSE
C26: =FALSE() -> FALSE
C27: =FALSE() -> FALSE
C28: =FALSE() -> FALSE
C29: =FALSE() -> FALSE
C30: =FALSE() -> FALSE
C31: =FALSE() -> FALSE
C32: =FALSE() -> FALSE
... C1001: =FALSE() -> FALSE

Sheet Reward Seasons
A1: Series | B1: Season | C1: Name | D1: Date | E1: PTS
A2: =FLOOR((ROW()+1)/(COUNTA(Seasons!$A$1:$A1003)+1),1) -> 0 | B2: 0 | C2: ="Series "&A2&IF(B2=0,"","/"&INDIRECT(ADDRESS(B2,1,1,TRUE(),"Seasons"))) -> Series 0 | D2: =IF(B2=0,VLOOKUP(A2,Series!$A$2:B1003,2,FALSE()),D1+IF(B1=0,0,7)) -> 44505 | E2: 4
A3: =FLOOR((ROW()+1)/(COUNTA(Seasons!$A$1:$A1003)+1),1) -> 0 | B3: =MOD(ROW()+1,COUNTA(Seasons!$A$1:$A1003)+1) -> 4 | C3: ="Series "&A3&IF(B3=0,"","/"&INDIRECT(ADDRESS(B3,1,1,TRUE(),"Seasons"))) -> Series 0/Spring | D3: =IF(B3=0,VLOOKUP(A3,Series!$A$2:B1003,2,FALSE()),D2+IF(B2=0,0,7)) -> 44505 | E3: 38
A4: =FLOOR((ROW()+1)/(COUNTA(Seasons!$A$1:$A1003)+1),1) -> 1 | B4: =MOD(ROW()+1,COUNTA(Seasons!$A$1:$A1003)+1) -> 0 | C4: ="Series "&A4&IF(B4=0,"","/"&INDIRECT(ADDRESS(B4,1,1,TRUE(),"Seasons"))) -> Series 1 | D4: =IF(B4=0,VLOOKUP(A4,Series!$A$2:B1003,2,FALSE()),D3+IF(B3=0,0,7)) -> 44511 | E4: 16
A5: =FLOOR((ROW()+1)/(COUNTA(Seasons!$A$1:$A1003)+1),1) -> 1 | B5: =MOD(ROW()+1,COUNTA(Seasons!$A$1:$A1003)+1) -> 1 | C5: ="Series "&A5&IF(B5=0,"","/"&INDIRECT(ADDRESS(B5,1,1,TRUE(),"Seasons"))) -> Series 1/Summer | D5: =IF(B5=0,VLOOKUP(A5,Series!$A$2:B1003,2,FALSE()),D4+IF(B4=0,0,7)) -> 44511 | E5: 64
A6: =FLOOR((ROW()+1)/(COUNTA(Seasons!$A$1:$A1003)+1),1) -> 1 | B6: =MOD(ROW()+1,COUNTA(Seasons!$A$1:$A1003)+1) -> 2 | C6: ="Series "&A6&IF(B6=0,"","/"&INDIRECT(ADDRESS(B6,1,1,TRUE(),"Seasons"))) -> Series 1/Autumn | D6: =IF(B6=0,VLOOKUP(A6,Series!$A$2:B1003,2,FALSE()),D5+IF(B5=0,0,7)) -> 44518 | E6: 61
A7: =FLOOR((ROW()+1)/(COUNTA(Seasons!$A$1:$A1003)+1),1) -> 1 | B7: =MOD(ROW()+1,COUNTA(Seasons!$A$1:$A1003)+1) -> 3 | C7: ="Series "&A7&IF(B7=0,"","/"&INDIRECT(ADDRESS(B7,1,1,TRUE(),"Seasons"))) -> Series 1/Winter | D7: =IF(B7=0,VLOOKUP(A7,Series!$A$2:B1003,2,FALSE()),D6+IF(B6=0,0,7)) -> 44525 | E7: 61
A8: =FLOOR((ROW()+1)/(COUNTA(Seasons!$A$1:$A1003)+1),1) -> 1 | B8: =MOD(ROW()+1,COUNTA(Seasons!$A$1:$A1003)+1) -> 4 | C8: ="Series "&A8&IF(B8=0,"","/"&INDIRECT(ADDRESS(B8,1,1,TRUE(),"Seasons"))) -> Series 1/Spring | D8: =IF(B8=0,VLOOKUP(A8,Series!$A$2:B1003,2,FALSE()),D7+IF(B7=0,0,7)) -> 44532 | E8: 61
A9: =FLOOR((ROW()+1)/(COUNTA(Seasons!$A$1:$A1003)+1),1) -> 2 | B9: =MOD(ROW()+1,COUNTA(Seasons!$A$1:$A1003)+1) -> 0 | C9: ="Series "&A9&IF(B9=0,"","/"&INDIRECT(ADDRESS(B9,1,1,TRUE(),"Seasons"))) -> Series 2 | D9: =IF(B9=0,VLOOKUP(A9,Series!$A$2:B1003,2,FALSE()),D8+IF(B8=0,0,7)) -> 44539 | E9: 16
A10: =FLOOR((ROW()+1)/(COUNTA(Seasons!$A$1:$A1003)+1),1) -> 2 | B10: =MOD(ROW()+1,COUNTA(Seasons!$A$1:$A1003)+1) -> 1 | C10: ="Series "&A10&IF(B10=0,"","/"&INDIRECT(ADDRESS(B10,1,1,TRUE(),"Seasons"))) -> Series 2/Summer | D10: =IF(B10=0,VLOOKUP(A10,Series!$A$2:B1003,2,FALSE()),D9+IF(B9=0,0,7)) -> 44539 | E10: 64
A11: =FLOOR((ROW()+1)/(COUNTA(Seasons!$A$1:$A1003)+1),1) -> 2 | B11: =MOD(ROW()+1,COUNTA(Seasons!$A$1:$A1003)+1) -> 2 | C11: ="Series "&A11&IF(B11=0,"","/"&INDIRECT(ADDRESS(B11,1,1,TRUE(),"Seasons"))) -> Series 2/Autumn | D11: =IF(B11=0,VLOOKUP(A11,Series!$A$2:B1003,2,FALSE()),D10+IF(B10=0,0,7)) -> 44546 | E11: 61
A12: =FLOOR((ROW()+1)/(COUNTA(Seasons!$A$1:$A1003)+1),1) -> 2 | B12: =MOD(ROW()+1,COUNTA(Seasons!$A$1:$A1003)+1) -> 3 | C12: ="Series "&A12&IF(B12=0,"","/"&INDIRECT(ADDRESS(B12,1,1,TRUE(),"Seasons"))) -> Series 2/Winter | D12: =IF(B12=0,VLOOKUP(A12,Series!$A$2:B1003,2,FALSE()),D11+IF(B11=0,0,7)) -> 44553 | E12: 61
A13: =FLOOR((ROW()+1)/(COUNTA(Seasons!$A$1:$A1003)+1),1) -> 2 | B13: =MOD(ROW()+1,COUNTA(Seasons!$A$1:$A1003)+1) -> 4 | C13: ="Series "&A13&IF(B13=0,"","/"&INDIRECT(ADDRESS(B13,1,1,TRUE(),"Seasons"))) -> Series 2/Spring | D13: =IF(B13=0,VLOOKUP(A13,Series!$A$2:B1003,2,FALSE()),D12+IF(B12=0,0,7)) -> 44560 | E13: 64
A14: =FLOOR((ROW()+1)/(COUNTA(Seasons!$A$1:$A1003)+1),1) -> 3 | B14: =MOD(ROW()+1,COUNTA(Seasons!$A$1:$A1003)+1) -> 0 | C14: ="Series "&A14&IF(B14=0,"","/"&INDIRECT(ADDRESS(B14,1,1,TRUE(),"Seasons"))) -> Series 3 | D14: =IF(B14=0,VLOOKUP(A14,Series!$A$2:B1003,2,FALSE()),D13+IF(B13=0,0,7)) -> 44567 | E14: 16
A15: =FLOOR((ROW()+1)/(COUNTA(Seasons!$A$1:$A1003)+1),1) -> 3 | B15: =MOD(ROW()+1,COUNTA(Seasons!$A$1:$A1003)+1) -> 1 | C15: ="Series "&A15&IF(B15=0,"","/"&INDIRECT(ADDRESS(B15,1,1,TRUE(),"Seasons"))) -> Series 3/Summer | D15: =IF(B15=0,VLOOKUP(A15,Series!$A$2:B1003,2,FALSE()),D14+IF(B14=0,0,7)) -> 44567 | E15: 64
A16: =FLOOR((ROW()+1)/(COUNTA(Seasons!$A$1:$A1003)+1),1) -> 3 | B16: =MOD(ROW()+1,COUNTA(Seasons!$A$1:$A1003)+1) -> 2 | C16: ="Series "&A16&IF(B16=0,"","/"&INDIRECT(ADDRESS(B16,1,1,TRUE(),"Seasons"))) -> Series 3/Autumn | D16: =IF(B16=0,VLOOKUP(A16,Series!$A$2:B1003,2,FALSE()),D15+IF(B15=0,0,7)) -> 44574 | E16: 61
A17: =FLOOR((ROW()+1)/(COUNTA(Seasons!$A$1:$A1003)+1),1) -> 3 | B17: =MOD(ROW()+1,COUNTA(Seasons!$A$1:$A1003)+1) -> 3 | C17: ="Series "&A17&IF(B17=0,"","/"&INDIRECT(ADDRESS(B17,1,1,TRUE(),"Seasons"))) -> Series 3/Winter | D17: =IF(B17=0,VLOOKUP(A17,Series!$A$2:B1003,2,FALSE()),D16+IF(B16=0,0,7)) -> 44581 | E17: 61
A18: =FLOOR((ROW()+1)/(COUNTA(Seasons!$A$1:$A1003)+1),1) -> 3 | B18: =MOD(ROW()+1,COUNTA(Seasons!$A$1:$A1003)+1) -> 4 | C18: ="Series "&A18&IF(B18=0,"","/"&INDIRECT(ADDRESS(B18,1,1,TRUE(),"Seasons"))) -> Series 3/Spring | D18: =IF(B18=0,VLOOKUP(A18,Series!$A$2:B1003,2,FALSE()),D17+IF(B17=0,0,7)) -> 44588 | E18: 64
A19: =FLOOR((ROW()+1)/(COUNTA(Seasons!$A$1:$A1003)+1),1) -> 4 | B19: =MOD(ROW()+1,COUNTA(Seasons!$A$1:$A1003)+1) -> 0 | C19: ="Series "&A19&IF(B19=0,"","/"&INDIRECT(ADDRESS(B19,1,1,TRUE(),"Seasons"))) -> Series 4 | D19: =IF(B19=0,VLOOKUP(A19,Series!$A$2:B1003,2,FALSE()),D18+IF(B18=0,0,7)) -> 44595 | E19: 16
A20: =FLOOR((ROW()+1)/(COUNTA(Seasons!$A$1:$A1003)+1),1) -> 4 | B20: =MOD(ROW()+1,COUNTA(Seasons!$A$1:$A1003)+1) -> 1 | C20: ="Series "&A20&IF(B20=0,"","/"&INDIRECT(ADDRESS(B20,1,1,TRUE(),"Seasons"))) -> Series 4/Summer | D20: =IF(B20=0,VLOOKUP(A20,Series!$A$2:B1003,2,FALSE()),D19+IF(B19=0,0,7)) -> 44595 | E20: 50
A21: =FLOOR((ROW()+1)/(COUNTA(Seasons!$A$1:$A1003)+1),1) -> 4 | B21: =MOD(ROW()+1,COUNTA(Seasons!$A$1:$A1003)+1) -> 2 | C21: ="Series "&A21&IF(B21=0,"","/"&INDIRECT(ADDRESS(B21,1,1,TRUE(),"Seasons"))) -> Series 4/Autumn | D21: =IF(B21=0,VLOOKUP(A21,Series!$A$2:B1003,2,FALSE()),D20+IF(B20=0,0,7)) -> 44602 | E21: 50
A22: =FLOOR((ROW()+1)/(COUNTA(Seasons!$A$1:$A1003)+1),1) -> 4 | B22: =MOD(ROW()+1,COUNTA(Seasons!$A$1:$A1003)+1) -> 3 | C22: ="Series "&A22&IF(B22=0,"","/"&INDIRECT(ADDRESS(B22,1,1,TRUE(),"Seasons"))) -> Series 4/Winter | D22: =IF(B22=0,VLOOKUP(A22,Series!$A$2:B1003,2,FALSE()),D21+IF(B21=0,0,7)) -> 44609 | E22: 50
A23: =FLOOR((ROW()+1)/(COUNTA(Seasons!$A$1:$A1003)+1),1) -> 4 | B23: =MOD(ROW()+1,COUNTA(Seasons!$A$1:$A1003)+1) -> 4 | C23: ="Series "&A23&IF(B23=0,"","/"&INDIRECT(ADDRESS(B23,1,1,TRUE(),"Seasons"))) -> Series 4/Spring | D23: =IF(B23=0,VLOOKUP(A23,Series!$A$2:B1003,2,FALSE()),D22+IF(B22=0,0,7)) -> 44616 | E23: 53
A24: =FLOOR((ROW()+1)/(COUNTA(Seasons!$A$1:$A1003)+1),1) -> 5 | B24: =MOD(ROW()+1,COUNTA(Seasons!$A$1:$A1003)+1) -> 0 | C24: ="Series "&A24&IF(B24=0,"","/"&INDIRECT(ADDRESS(B24,1,1,TRUE(),"Seasons"))) -> Series 5 | D24: =IF(B24=0,VLOOKUP(A24,Series!$A$2:B1003,2,FALSE()),D23+IF(B23=0,0,7)) -> 44623 | E24: 16
A25: =FLOOR((ROW()+1)/(COUNTA(Seasons!$A$1:$A1003)+1),1) -> 5 | B25: =MOD(ROW()+1,COUNTA(Seasons!$A$1:$A1003)+1) -> 1 | C25: ="Series "&A25&IF(B25=0,"","/"&INDIRECT(ADDRESS(B25,1,1,TRUE(),"Seasons"))) -> Series 5/Summer | D25: =IF(B25=0,VLOOKUP(A25,Series!$A$2:B1003,2,FALSE()),D24+IF(B24=0,0,7)) -> 44623 | E25: 49
A26: =FLOOR((ROW()+1)/(COUNTA(Seasons!$A$1:$A1003)+1),1) -> 5 | B26: =MOD(ROW()+1,COUNTA(Seasons!$A$1:$A1003)+1) -> 2 | C26: ="Series "&A26&IF(B26=0,"","/"&INDIRECT(ADDRESS(B26,1,1,TRUE(),"Seasons"))) -> Series 5/Autumn | D26: =IF(B26=0,VLOOKUP(A26,Series!$A$2:B1003,2,FALSE()),D25+IF(B25=0,0,7)) -> 44630 | E26: 48
A27: =FLOOR((ROW()+1)/(COUNTA(Seasons!$A$1:$A1003)+1),1) -> 5 | B27: =MOD(ROW()+1,COUNTA(Seasons!$A$1:$A1003)+1) -> 3 | C27: ="Series "&A27&IF(B27=0,"","/"&INDIRECT(ADDRESS(B27,1,1,TRUE(),"Seasons"))) -> Series 5/Winter | D27: =IF(B27=0,VLOOKUP(A27,Series!$A$2:B1003,2,FALSE()),D26+IF(B26=0,0,7)) -> 44637 | E27: 47
A28: =FLOOR((ROW()+1)/(COUNTA(Seasons!$A$1:$A1003)+1),1) -> 5 | B28: =MOD(ROW()+1,COUNTA(Seasons!$A$1:$A1003)+1) -> 4 | C28: ="Series "&A28&IF(B28=0,"","/"&INDIRECT(ADDRESS(B28,1,1,TRUE(),"Seasons"))) -> Series 5/Spring | D28: =IF(B28=0,VLOOKUP(A28,Series!$A$2:B1003,2,FALSE()),D27+IF(B27=0,0,7)) -> 44644 | E28: 48
A29: =FLOOR((ROW()+1)/(COUNTA(Seasons!$A$1:$A1003)+1),1) -> 6 | B29: =MOD(ROW()+1,COUNTA(Seasons!$A$1:$A1003)+1) -> 0 | C29: ="Series "&A29&IF(B29=0,"","/"&INDIRECT(ADDRESS(B29,1,1,TRUE(),"Seasons"))) -> Series 6 | D29: =IF(B29=0,VLOOKUP(A29,Series!$A$2:B1003,2,FALSE()),D28+IF(B28=0,0,7)) -> 44651 | E29: 28
A30: =FLOOR((ROW()+1)/(COUNTA(Seasons!$A$1:$A1003)+1),1) -> 6 | B30: =MOD(ROW()+1,COUNTA(Seasons!$A$1:$A1003)+1) -> 1 | C30: ="Series "&A30&IF(B30=0,"","/"&INDIRECT(ADDRESS(B30,1,1,TRUE(),"Seasons"))) -> Series 6/Summer | D30: =IF(B30=0,VLOOKUP(A30,Series!$A$2:B1003,2,FALSE()),D29+IF(B29=0,0,7)) -> 44651 | E30: 51
A31: =FLOOR((ROW()+1)/(COUNTA(Seasons!$A$1:$A1003)+1),1) -> 6 | B31: =MOD(ROW()+1,COUNTA(Seasons!$A$1:$A1003)+1) -> 2 | C31: ="Series "&A31&IF(B31=0,"","/"&INDIRECT(ADDRESS(B31,1,1,TRUE(),"Seasons"))) -> Series 6/Autumn | D31: =IF(B31=0,VLOOKUP(A31,Series!$A$2:B1003,2,FALSE()),D30+IF(B30=0,0,7)) -> 44658 | E31: 50
A32: =FLOOR((ROW()+1)/(COUNTA(Seasons!$A$1:$A1003)+1),1) -> 6 | B32: =MOD(ROW()+1,COUNTA(Seasons!$A$1:$A1003)+1) -> 3 | C32: ="Series "&A32&IF(B32=0,"","/"&INDIRECT(ADDRESS(B32,1,1,TRUE(),"Seasons"))) -> Series 6/Winter | D32: =IF(B32=0,VLOOKUP(A32,Series!$A$2:B1003,2,FALSE()),D31+IF(B31=0,0,7)) -> 44665 | E32: 50
A33: =FLOOR((ROW()+1)/(COUNTA(Seasons!$A$1:$A1003)+1),1) -> 6 | B33: =MOD(ROW()+1,COUNTA(Seasons!$A$1:$A1003)+1) -> 4 | C33: ="Series "&A33&IF(B33=0,"","/"&INDIRECT(ADDRESS(B33,1,1,TRUE(),"Seasons"))) -> Series 6/Spring | D33: =IF(B33=0,VLOOKUP(A33,Series!$A$2:B1003,2,FALSE()),D32+IF(B32=0,0,7)) -> 44672 | E33: 51
A34: =FLOOR((ROW()+1)/(COUNTA(Seasons!$A$1:$A1003)+1),1) -> 7 | B34: =MOD(ROW()+1,COUNTA(Seasons!$A$1:$A1003)+1) -> 0 | C34: ="Series "&A34&IF(B34=0,"","/"&INDIRECT(ADDRESS(B34,1,1,TRUE(),"Seasons"))) -> Series 7 | D34: =IF(B34=0,VLOOKUP(A34,Series!$A$2:B1003,2,FALSE()),D33+IF(B33=0,0,7)) -> 44679 | E34: 4
A35: =FLOOR((ROW()+1)/(COUNTA(Seasons!$A$1:$A1003)+1),1) -> 7 | B35: =MOD(ROW()+1,COUNTA(Seasons!$A$1:$A1003)+1) -> 1 | C35: ="Series "&A35&IF(B35=0,"","/"&INDIRECT(ADDRESS(B35,1,1,TRUE(),"Seasons"))) -> Series 7/Summer | D35: =IF(B35=0,VLOOKUP(A35,Series!$A$2:B1003,2,FALSE()),D34+IF(B34=0,0,7)) -> 44679 | E35: 53
A36: =FLOOR((ROW()+1)/(COUNTA(Seasons!$A$1:$A1003)+1),1) -> 7 | B36: =MOD(ROW()+1,COUNTA(Seasons!$A$1:$A1003)+1) -> 2 | C36: ="Series "&A36&IF(B36=0,"","/"&INDIRECT(ADDRESS(B36,1,1,TRUE(),"Seasons"))) -> Series 7/Autumn | D36: =IF(B36=0,VLOOKUP(A36,Series!$A$2:B1003,2,FALSE()),D35+IF(B35=0,0,7)) -> 44686 | E36: 51
A37: =FLOOR((ROW()+1)/(COUNTA(Seasons!$A$1:$A1003)+1),1) -> 7 | B37: =MOD(ROW()+1,COUNTA(Seasons!$A$1:$A1003)+1) -> 3 | C37: ="Series "&A37&IF(B37=0,"","/"&INDIRECT(ADDRESS(B37,1,1,TRUE(),"Seasons"))) -> Series 7/Winter | D37: =IF(B37=0,VLOOKUP(A37,Series!$A$2:B1003,2,FALSE()),D36+IF(B36=0,0,7)) -> 44693 | E37: 52
A38: =FLOOR((ROW()+1)/(COUNTA(Seasons!$A$1:$A1003)+1),1) -> 7 | B38: =MOD(ROW()+1,COUNTA(Seasons!$A$1:$A1003)+1) -> 4 | C38: ="Series "&A38&IF(B38=0,"","/"&INDIRECT(ADDRESS(B38,1,1,TRUE(),"Seasons"))) -> Series 7/Spring | D38: =IF(B38=0,VLOOKUP(A38,Series!$A$2:B1003,2,FALSE()),D37+IF(B37=0,0,7)) -> 44700 | E38: 53
A39: =FLOOR((ROW()+1)/(COUNTA(Seasons!$A$1:$A1003)+1),1) -> 8 | B39: =MOD(ROW()+1,COUNTA(Seasons!$A$1:$A1003)+1) -> 0 | C39: ="Series "&A39&IF(B39=0,"","/"&INDIRECT(ADDRESS(B39,1,1,TRUE(),"Seasons"))) -> Series 8 | D39: =IF(B39=0,VLOOKUP(A39,Series!$A$2:B1003,2,FALSE()),D38+IF(B38=0,0,7)) -> 44707 | E39: 4
A40: =FLOOR((ROW()+1)/(COUNTA(Seasons!$A$1:$A1003)+1),1) -> 8 | B40: =MOD(ROW()+1,COUNTA(Seasons!$A$1:$A1003)+1) -> 1 | C40: ="Series "&A40&IF(B40=0,"","/"&INDIRECT(ADDRESS(B40,1,1,TRUE(),"Seasons"))) -> Series 8/Summer | D40: =IF(B40=0,VLOOKUP(A40,Series!$A$2:B1003,2,FALSE()),D39+IF(B39=0,0,7)) -> 44707 | E40: 51
...

Sheet Classifications
A1: Barn Find
A2: Accolade
A3: Autoshow
A4: Car Collector
A5: Car Mastery
A6: Wheelspin
A7: Reward
A8: DLC
A9: Promo
A10: Unreleased

Sheet Reward Types
A1: Season Reward
A2: Playground Games
A3: Seasonal Championship
A4: Series Reward
A5: Super7
A6: The Trial
A7: Event Reward
A8: Event Lab
A9: Collectibles
A10: Showcase Remix
A11: Danger Sign
A12: Speed Trap
... A20: Gift

Sheet Series
A1: Number | B1: Date | C1: Name
A2: =ROW()-2 -> 0 | B2: 44505 | C2: Welcome Week
A3: =ROW()-2 -> 1 | B3: 44511 | C3: Welcome to Mexico
A4: =ROW()-2 -> 2 | B4: =B3+28 -> 44539 | C4: Holiday Special
A5: =ROW()-2 -> 3 | B5: =B4+28 -> 44567 | C5: Happy New Year
A6: =ROW()-2 -> 4 | B6: =B5+28 -> 44595 | C6: Horizon World Cup
A7: =ROW()-2 -> 5 | B7: =B6+28 -> 44623 | C7: Horizon Rush Takeover
A8: =ROW()-2 -> 6 | B8: =B7+28 -> 44651 | C8: Horizon Customs
A9: =ROW()-2 -> 7 | B9: =B8+28 -> 44679 | C9: Cinco de Mayo
A10: =ROW()-2 -> 8 | B10: =B9+28 -> 44707 | C10: German Automotive Excellence
A11: =ROW()-2 -> 9 | B11: =B10+28 -> 44735 | C11: Hot Wheels
A12: =ROW()-2 -> 10 | B12: =B11+28 -> 44763 | C12: Extreme E
A13: =ROW()-2 -> 11 | B13: =B12+28 -> 44791 | C13: Rami's Racing History
A14: =ROW()-2 -> 12 | B14: =B13+28 -> 44819 | C14: Horizon Road Trip
A15: =ROW()-2 -> 13 | B15: =B14+28 -> 44847 | C15: Horizon 10-Year Anniversary
... A36: =ROW()-2 -> 34 | B36: =B35+28 -> 45435 | C36: Horizon Retrowave
A37: =ROW()-2 -> 35 | B37: =B36+28 -> 45463
A38: =ROW()-2 -> 36 | B38: =B37+28 -> 45491
A39: =ROW()-2 -> 37 | B39: =B38+28 -> 45519
A40: =ROW()-2 -> 38 | B40: =B39+28 -> 45547
A41: =ROW()-2 -> 39 | B41: =B40+28 -> 45575
A42: =ROW()-2 -> 40 | B42: =B41+28 -> 45603
A43: =ROW()-2 -> 41 | B43: =B42+28 -> 45631
A44: =ROW()-2 -> 42 | B44: =B43+28 -> 45659
A45: =ROW()-2 -> 43 | B45: =B44+28 -> 45687
A46: =ROW()-2 -> 44 | B46: =B45+28 -> 45715
A47: =ROW()-2 -> 45 | B47: =B46+28 -> 45743
A48: =ROW()-2 -> 46 | B48: =B47+28 -> 45771
... A101: =ROW()-2 -> 99 | B101: =B100+28 -> 47255

Sheet Seasons
A1: Summer
A2: Autumn
A3: Winter
A4: Spring

Sheet Season Start
A1: =TIME(16,30,0) -> 0.6875 | B1: =NOW() -> 45672.082

Sheet Rarities
A1: - | B1: 0
A2: Common | B2: 1
A3: Rare | B3: 2
A4: Epic | B4: 3
A5: Legendary | B5: 4
A6: Forza Edition | B6: 5
A7: Anniversary Edition | B7: 6
A8: Donut Edition | B8: 6

Sheet Types
A1: -
A2: Buggies
A3: Classic Muscle
A4: Classic Racers
A5: Classic Rally
A6: Classic Sports Cars
A7: Cult Classics
A8: Drift Cars
A9: Extreme Track Toys
A10: GT Cars
A11: Hot Hatch
A12: Hypercars
... A38: Vintage Racers

Sheet Manufacturers
A1: Abarth | B1: IT
A2: Acura | B2: US
A3: Alejandra's | B3: -
A4: Alfa Romeo | B4: IT
A5: Alpine | B5: FR
A6: Alumnicraft | B6: US
A7: AMC | B7: US
A8: AMG Transport Dynamics | B8: US
A9: Apollo | B9: DE
A10: Ariel | B10: GB
A11: Ascari | B11: GB
A12: Aston Martin | B12: GB
... A131: Zenvo | B131: DK

Sheet Countries
A1: - | B1: =IF(A1="-",A1,image("https://public.flourish.studio/country-flags/svg/"&LOWER(A1)&".svg",2)) -> -
A2: AE | B2: =IF(A2="-",A2,image("https://public.flourish.studio/country-flags/svg/"&LOWER(A2)&".svg",2)) -> #NAME?
A3: AT | B3: =IF(A3="-",A3,image("https://public.flourish.studio/country-flags/svg/"&LOWER(A3)&".svg",2)) -> #NAME?
A4: AU | B4: =IF(A4="-",A4,image("https://public.flourish.studio/country-flags/svg/"&LOWER(A4)&".svg",2)) -> #NAME?
A5: CA | B5: =IF(A5="-",A5,image("https://public.flourish.studio/country-flags/svg/"&LOWER(A5)&".svg",2)) -> #NAME?
A6: CN | B6: =IF(A6="-",A6,image("https://public.flourish.studio/country-flags/svg/"&LOWER(A6)&".svg",2)) -> #NAME?
A7: DE | B7: =IF(A7="-",A7,image("https://public.flourish.studio/country-flags/svg/"&LOWER(A7)&".svg",2)) -> #NAME?
A8: DK | B8: =IF(A8="-",A8,image("https://public.flourish.studio/country-flags/svg/"&LOWER(A8)&".svg",2)) -> #NAME?
A9: ES | B9: =IF(A9="-",A9,image("https://public.flourish.studio/country-flags/svg/"&LOWER(A9)&".svg",2)) -> #NAME?
A10: FR | B10: =IF(A10="-",A10,image("https://public.flourish.studio/country-flags/svg/"&LOWER(A10)&".svg",2)) -> #NAME?
A11: GB | B11: =IF(A11="-",A11,image("https://public.flourish.studio/country-flags/svg/"&LOWER(A11)&".svg",2)) -> #NAME?
A12: HR | B12: =IF(A12="-",A12,image("https://public.flourish.studio/country-flags/svg/"&LOWER(A12)&".svg",2)) -> #NAME?
... A19: US | B19: =IF(A19="-",A19,image("https://public.flourish.studio/country-flags/svg/"&LOWER(A19)&".svg",2)) -> #NAME?

Sheet Reward Categories
A1: Exclusive | B1: 4
A2: Hard to Find | B2: 3
A3: Valuable | B3: 2
A4: Common | B4: 1

Sheet Wheelspin Rewards
A1: 1000 | B1: Common
A2: 2000 | B2: Common
A3: 4000 | B3: Common
A4: 5000 | B4: Common
A5: 10000 | B5: Common
A6: 15000 | B6: Common
A7: 20000 | B7: Common
A8: 25000 | B8: Common
A9: 30000 | B9: Common
A10: 35000 | B10: Common
A11: 40000 | B11: Common
A12: 45000 | B12: Common
... A21: 300000 | B21: Legendary
